<?xml version="1.0" ?>
<sdf version="1.6">
  <model name="submarine">
    <pose>0 0 0 1.5707963267948966 1.5707963267948966 0</pose>

    <link name="body">
      <pose>0 0 0 0 1.5707963267948966 0</pose>
      <inertial>
        <pose>0 0 -0.02 0 0 0</pose>
        <mass>102</mass>
        <inertia><ixx>1.64</ixx><iyy>18.33</iyy><izz>18.33</izz><ixy>0</ixy><ixz>0</ixz><iyz>0</iyz></inertia>
        <fluid_added_mass><xx>5.8</xx><yy>116.0</yy><zz>116.0</zz><pp>0.7</pp><qq>0.5</qq><rr>0.5</rr></fluid_added_mass>
      </inertial>
      <visual name="body_visual"><geometry><cylinder><radius>0.1666667</radius><length>1.3333333</length></cylinder></geometry><material><ambient>0.2 0.5 0.8 1</ambient></material></visual>
      <collision name="body_collision"><geometry><cylinder><radius>0.1666667</radius><length>1.3333333</length></cylinder></geometry></collision>
      <sensor name="imu_sensor" type="imu"><always_on>1</always_on><update_rate>100</update_rate><topic>/model/submarine/imu</topic></sensor>
      <sensor name="pressure_sensor" type="air_pressure"><always_on>1</always_on><update_rate>50</update_rate><topic>/sub_press</topic></sensor>
    </link>

    <!-- ЛЕВЫЙ ПРОПЕЛЛЕР -->
    <link name="left_propeller">
      <pose>0 0.2833333 0 0 1.5708 0</pose>
      <inertial><mass>0.101</mass><inertia><ixx>0.0000592</ixx><iyy>0.0000592</iyy><izz>0.000117</izz><ixy>0</ixy><ixz>0</ixz><iyz>0</iyz></inertia></inertial>
      <visual name="lp_cyl"><geometry><cylinder><radius>0.0333</radius><length>0.03</length></cylinder></geometry><material><ambient>0.8 0.8 0.8 1</ambient></material></visual>
      <visual name="lp_b1"><pose>0.057 0 0 -0.349066 0 0</pose><geometry><box><size>0.1 0.05 0.01</size></box></geometry><material><ambient>0.8 0.8 0.8 1</ambient></material></visual>
      <visual name="lp_b2"><pose>-0.057 0 0 0.349066 0 0</pose><geometry><box><size>0.1 0.05 0.01</size></box></geometry><material><ambient>0.8 0.8 0.8 1</ambient></material></visual>
      <visual name="lp_b3"><pose>0 0.057 0 0 -0.349066 0</pose><geometry><box><size>0.05 0.1 0.01</size></box></geometry><material><ambient>0.8 0.8 0.8 1</ambient></material></visual>
      <visual name="lp_b4"><pose>0 -0.057 0 0 0.349066  0</pose><geometry><box><size>0.05 0.1 0.01</size></box></geometry><material><ambient>0.8 0.8 0.8 1</ambient></material></visual>
      <collision name="lp_c1"><pose>0.057 0 0 -0.349066 0 0</pose><geometry><box><size>0.1 0.05 0.01</size></box></geometry></collision>
      <collision name="lp_c2"><pose>-0.057 0 0 0.349066 0 0</pose><geometry><box><size>0.1 0.05 0.01</size></box></geometry></collision>
      <collision name="lp_c3"><pose>0 0.057 0 0 -0.349066 0</pose><geometry><box><size>0.05 0.1 0.01</size></box></geometry></collision>
      <collision name="lp_c4"><pose>0 -0.057 0 0 0.349066 0</pose><geometry><box><size>0.05 0.1 0.01</size></box></geometry></collision>
    </link>
    <joint name="left_propeller_joint" type="revolute"><parent>body</parent><child>left_propeller</child><axis><xyz>1 0 0</xyz><use_parent_model_frame>1</use_parent_model_frame><limit><lower>-1e12</lower><upper>1e12</upper></limit><dynamics><damping>0.5</damping></dynamics></axis></joint>
    <plugin filename="gz-sim-apply-joint-force-system" name="gz::sim::systems::ApplyJointForce"><joint_name>left_propeller_joint</joint_name></plugin>
    <plugin filename="gz-sim-lift-drag-system" name="gz::sim::systems::LiftDrag"><air_density>1000</air_density><cla>1.2535816618911175</cla><cla_stall>-1.4326647564469914</cla_stall><cda>0.02</cda><cda_stall>1.4326647564469914</cda_stall><alpha_stall>1.396</alpha_stall><area>0.007677</area><upward>0 -0.7071067811865476 -0.7071067811865475</upward><forward>0 -0.7071067811865475 0.7071067811865476</forward><link_name>left_propeller</link_name><cp>0.05833 0 0</cp></plugin>
    <plugin filename="gz-sim-lift-drag-system" name="gz::sim::systems::LiftDrag"><air_density>1000</air_density><cla>1.2535816618911175</cla><cla_stall>-1.4326647564469914</cla_stall><cda>0.02</cda><cda_stall>1.4326647564469914</cda_stall><alpha_stall>1.396</alpha_stall><area>0.007677</area><upward>-0.7071067811865475 0 -0.7071067811865476</upward><forward>-0.7071067811865476 0 0.7071067811865475</forward><link_name>left_propeller</link_name><cp>0 -0.05833 0</cp></plugin>
    <plugin filename="gz-sim-lift-drag-system" name="gz::sim::systems::LiftDrag"><air_density>1000</air_density><cla>1.2535816618911175</cla><cla_stall>-1.4326647564469914</cla_stall><cda>0.02</cda><cda_stall>1.4326647564469914</cda_stall><alpha_stall>1.396</alpha_stall><area>0.007677</area><upward>0 0.7071067811865475 -0.7071067811865476</upward><forward>0 0.7071067811865476 0.7071067811865475</forward><link_name>left_propeller</link_name><cp>-0.05833 0 0</cp></plugin>
    <plugin filename="gz-sim-lift-drag-system" name="gz::sim::systems::LiftDrag"><air_density>1000</air_density><cla>1.2535816618911175</cla><cla_stall>-1.4326647564469914</cla_stall><cda>0.02</cda><cda_stall>1.4326647564469914</cda_stall><alpha_stall>1.396</alpha_stall><area>0.007677</area><upward>0.7071067811865476 0 -0.7071067811865475</upward><forward>0.7071067811865475 0 0.7071067811865476</forward><link_name>left_propeller</link_name><cp>0 0.05833 0</cp></plugin>

    <!-- ПРАВЫЙ ПРОПЕЛЛЕР -->
    <link name="right_propeller">
      <pose>0 -0.2833333 0 0 1.5708 0</pose>
      <inertial><mass>0.101</mass><inertia><ixx>0.0000592</ixx><iyy>0.0000592</iyy><izz>0.000117</izz><ixy>0</ixy><ixz>0</ixz><iyz>0</iyz></inertia></inertial>
      <visual name="rp_cyl"><geometry><cylinder><radius>0.0333</radius><length>0.03</length></cylinder></geometry><material><ambient>0.8 0.8 0.8 1</ambient></material></visual>
      <visual name="rp_b1"><pose>0.057 0 0 0.349066 0 0</pose><geometry><box><size>0.1 0.05 0.01</size></box></geometry><material><ambient>0.8 0.8 0.8 1</ambient></material></visual>
      <visual name="rp_b2"><pose>-0.057 0 0 -0.349066 0 0</pose><geometry><box><size>0.1 0.05 0.01</size></box></geometry><material><ambient>0.8 0.8 0.8 1</ambient></material></visual>
      <visual name="rp_b3"><pose>0 0.057 0 0 0.349066 0</pose><geometry><box><size>0.05 0.1 0.01</size></box></geometry><material><ambient>0.8 0.8 0.8 1</ambient></material></visual>
      <visual name="rp_b4"><pose>0 -0.057 0 0 -0.349066 0</pose><geometry><box><size>0.05 0.1 0.01</size></box></geometry><material><ambient>0.8 0.8 0.8 1</ambient></material></visual>
      <collision name="rp_c1"><pose>0.057 0 0 0.349066 0 0</pose><geometry><box><size>0.1 0.05 0.01</size></box></geometry></collision>
      <collision name="rp_c2"><pose>-0.057 0 0 -0.349066 0 0</pose><geometry><box><size>0.1 0.05 0.01</size></box></geometry></collision>
      <collision name="rp_c3"><pose>0 0.057 0 0 0.349066 0</pose><geometry><box><size>0.05 0.1 0.01</size></box></geometry></collision>
      <collision name="rp_c4"><pose>0 -0.057 0 0 -0.349066 0</pose><geometry><box><size>0.05 0.1 0.01</size></box></geometry></collision>
    </link>
    <joint name="right_propeller_joint" type="revolute"><parent>body</parent><child>right_propeller</child><axis><xyz>-1 0 0</xyz><use_parent_model_frame>1</use_parent_model_frame><limit><lower>-1e12</lower><upper>1e12</upper></limit><dynamics><damping>0.5</damping></dynamics></axis></joint>
    <plugin filename="gz-sim-apply-joint-force-system" name="gz::sim::systems::ApplyJointForce"><joint_name>right_propeller_joint</joint_name></plugin>
    <plugin filename="gz-sim-lift-drag-system" name="gz::sim::systems::LiftDrag"><air_density>1000</air_density><cla>1.2535816618911175</cla><cla_stall>-1.4326647564469914</cla_stall><cda>0.02</cda><cda_stall>1.4326647564469914</cda_stall><alpha_stall>1.396</alpha_stall><area>0.007677</area><upward>0 0.7071067811865476 -0.7071067811865475</upward><forward>0 0.7071067811865475 0.7071067811865476</forward><link_name>right_propeller</link_name><cp>0.05833 0 0</cp></plugin>
    <plugin filename="gz-sim-lift-drag-system" name="gz::sim::systems::LiftDrag"><air_density>1000</air_density><cla>1.2535816618911175</cla><cla_stall>-1.4326647564469914</cla_stall><cda>0.02</cda><cda_stall>1.4326647564469914</cda_stall><alpha_stall>1.396</alpha_stall><area>0.007677</area><upward>0.7071067811865475 0 -0.7071067811865476</upward><forward>0.7071067811865476 0 0.7071067811865475</forward><link_name>right_propeller</link_name><cp>0 -0.05833 0</cp></plugin>
    <plugin filename="gz-sim-lift-drag-system" name="gz::sim::systems::LiftDrag"><air_density>1000</air_density><cla>1.2535816618911175</cla><cla_stall>-1.4326647564469914</cla_stall><cda>0.02</cda><cda_stall>1.4326647564469914</cda_stall><alpha_stall>1.396</alpha_stall><area>0.007677</area><upward>0 -0.7071067811865475 -0.7071067811865476</upward><forward>0 -0.7071067811865476 0.7071067811865475</forward><link_name>right_propeller</link_name><cp>-0.05833 0 0</cp></plugin>
    <plugin filename="gz-sim-lift-drag-system" name="gz::sim::systems::LiftDrag"><air_density>1000</air_density><cla>1.2535816618911175</cla><cla_stall>-1.4326647564469914</cla_stall><cda>0.02</cda><cda_stall>1.4326647564469914</cda_stall><alpha_stall>1.396</alpha_stall><area>0.007677</area><upward>-0.7071067811865476 0 -0.7071067811865475</upward><forward>-0.7071067811865475 0 0.7071067811865476</forward><link_name>right_propeller</link_name><cp>0 0.05833 0</cp></plugin>

    <!-- РУЛИ — ОРИГИНАЛ -->
    <link name="horizontal_rudder_right">
      <pose>-0.6666667 0.2833333 0 1.5708 0 1.5708</pose>
      <inertial><mass>0.02315</mass><inertia><ixx>0.00000129</ixx><iyy>0.00000129</iyy><izz>0.00000129</izz><ixy>0</ixy><ixz>0</ixz><iyz>0</iyz></inertia></inertial>
      <visual name="hrr_v"><geometry><box><size>0.1666667 0.0083333 0.0833333</size></box></geometry><material><ambient>0.2 0.5 0.8 1</ambient></material></visual>
      <collision name="hrr_c"><geometry><box><size>0.05 0.0083333 0.0833333</size></box></geometry></collision>
    </link>
    <joint name="horizontal_rudder_right_joint" type="revolute"><parent>body</parent><child>horizontal_rudder_right</child><axis><xyz>1 0 0</xyz><limit><lower>-0.785</lower><upper>0.785</upper><effort>10</effort><velocity>1.0</velocity></limit><dynamics><damping>10</damping></dynamics></axis></joint>
    <plugin filename="gz-sim-joint-position-controller-system" name="gz::sim::systems::JointPositionController"><joint_name>horizontal_rudder_right_joint</joint_name><topic>/model/submarine/joint/horizontal_rudder_right/cmd_position</topic><p_gain>10</p_gain></plugin>
    <plugin filename="gz-sim-lift-drag-system" name="gz::sim::systems::LiftDrag">
      <air_density>1000</air_density><link_name>horizontal_rudder_right</link_name>
      <area>0.014</area><cla>2.5</cla><cla_stall>-0.5</cla_stall>
      <cda>0.5</cda><cda_stall>1.0</cda_stall><alpha_stall>1.2</alpha_stall><a0>0</a0>
      <upward>0 1 0</upward><forward>0 0 1</forward>
      <cp>-0.6666667 0.2833333 0</cp>
    </plugin>

    <link name="horizontal_rudder_left">
      <pose>-0.6666667 -0.2833333 0 1.5708 0 1.5708</pose>
      <inertial><mass>0.02315</mass><inertia><ixx>0.00000129</ixx><iyy>0.00000129</iyy><izz>0.00000129</izz><ixy>0</ixy><ixz>0</ixz><iyz>0</iyz></inertia></inertial>
      <visual name="hrl_v"><geometry><box><size>0.1666667 0.0083333 0.0833333</size></box></geometry><material><ambient>0.2 0.5 0.8 1</ambient></material></visual>
      <collision name="hrl_c"><geometry><box><size>0.05 0.0083333 0.0833333</size></box></geometry></collision>
    </link>
    <joint name="horizontal_rudder_left_joint" type="revolute"><parent>body</parent><child>horizontal_rudder_left</child><axis><xyz>1 0 0</xyz><limit><lower>-0.785</lower><upper>0.785</upper><effort>10</effort><velocity>1.0</velocity></limit><dynamics><damping>10</damping></dynamics></axis></joint>
    <plugin filename="gz-sim-joint-position-controller-system" name="gz::sim::systems::JointPositionController"><joint_name>horizontal_rudder_left_joint</joint_name><topic>/model/submarine/joint/horizontal_rudder_left/cmd_position</topic><p_gain>10</p_gain></plugin>
    <plugin filename="gz-sim-lift-drag-system" name="gz::sim::systems::LiftDrag">
      <air_density>1000</air_density><link_name>horizontal_rudder_left</link_name>
      <area>0.014</area><cla>2.5</cla><cla_stall>-0.5</cla_stall>
      <cda>0.5</cda><cda_stall>1.0</cda_stall><alpha_stall>1.2</alpha_stall><a0>0</a0>
      <upward>0 1 0</upward><forward>0 0 1</forward>
      <cp>-0.6666667 -0.2833333 0</cp>
    </plugin>

    <link name="vertical_rudder">
      <pose>-0.7666667 0 -0.2833333 1.5708 1.5708 0</pose>
      <inertial><mass>0.02315</mass><inertia><ixx>0.00000129</ixx><iyy>0.00000129</iyy><izz>0.00000129</izz><ixy>0</ixy><ixz>0</ixz><iyz>0</iyz></inertia></inertial>
      <visual name="vr_v"><geometry><box><size>0.1666667 0.1666667 0.005</size></box></geometry><material><ambient>0.2 0.5 0.8 1</ambient></material></visual>
      <collision name="vr_c"><geometry><box><size>0.0333333 0.0666667 0.005</size></box></geometry></collision>
    </link>
    <joint name="vertical_rudder_joint" type="revolute"><parent>body</parent><child>vertical_rudder</child><axis><xyz>1 0 0</xyz><limit><lower>-0.785</lower><upper>0.785</upper><effort>10</effort><velocity>1.0</velocity></limit><dynamics><damping>10</damping></dynamics></axis></joint>
    <plugin filename="gz-sim-joint-position-controller-system" name="gz::sim::systems::JointPositionController"><joint_name>vertical_rudder_joint</joint_name><topic>/model/submarine/joint/vertical_rudder/cmd_position</topic><p_gain>10</p_gain></plugin>
    <plugin filename="gz-sim-lift-drag-system" name="gz::sim::systems::LiftDrag">
      <air_density>1000</air_density><link_name>vertical_rudder</link_name>
      <area>0.028</area><cla>2.5</cla><cla_stall>-0.5</cla_stall>
      <cda>0.5</cda><cda_stall>1.0</cda_stall><alpha_stall>1.2</alpha_stall><a0>0</a0>
      <upward>0 0 1</upward><forward>0 1 0</forward>
      <cp>-0.7666667 0 -0.2833333</cp>
    </plugin>

    <!-- БАЛЛАСТЫ -->
    <link name="ballast_1"><pose>0.49 0 -0.2 0 0 0</pose><inertial><mass>5.88</mass><inertia><ixx>0.0001</ixx><iyy>0.0001</iyy><izz>0.0001</izz></inertia></inertial><visual name="b1_v"><geometry><box><size>0.32 0.05 0.05</size></box></geometry><material><ambient>0.8 0.2 0.2 1</ambient></material></visual><collision name="b1_c"><geometry><box><size>0.32 0.05 0.05</size></box></geometry></collision></link>
    <joint name="ballast_1_joint" type="fixed"><parent>body</parent><child>ballast_1</child></joint>
    <link name="ballast_2"><pose>0.17 0 -0.2 0 0 0</pose><inertial><mass>5.25</mass><inertia><ixx>0.0001</ixx><iyy>0.0001</iyy><izz>0.0001</izz></inertia></inertial><visual name="b2_v"><geometry><box><size>0.32 0.05 0.05</size></box></geometry><material><ambient>0.8 0.2 0.2 1</ambient></material></visual><collision name="b2_c"><geometry><box><size>0.32 0.05 0.05</size></box></geometry></collision></link>
    <joint name="ballast_2_joint" type="fixed"><parent>body</parent><child>ballast_2</child></joint>
    <link name="ballast_3"><pose>-0.17 0 -0.2 0 0 0</pose><inertial><mass>3.0</mass><inertia><ixx>0.0001</ixx><iyy>0.0001</iyy><izz>0.0001</izz></inertia></inertial><visual name="b3_v"><geometry><box><size>0.32 0.05 0.05</size></box></geometry><material><ambient>0.8 0.2 0.2 1</ambient></material></visual><collision name="b3_c"><geometry><box><size>0.32 0.05 0.05</size></box></geometry></collision></link>
    <joint name="ballast_3_joint" type="fixed"><parent>body</parent><child>ballast_3</child></joint>
    <link name="ballast_4"><pose>-0.49 0 -0.2 0 0 0</pose><inertial><mass>2.554</mass><inertia><ixx>0.0001</ixx><iyy>0.0001</iyy><izz>0.0001</izz></inertia></inertial><visual name="b4_v"><geometry><box><size>0.32 0.05 0.05</size></box></geometry><material><ambient>0.8 0.2 0.2 1</ambient></material></visual><collision name="b4_c"><geometry><box><size>0.32 0.05 0.05</size></box></geometry></collision></link>
    <joint name="ballast_4_joint" type="fixed"><parent>body</parent><child>ballast_4</child></joint>

    <plugin filename="gz-sim-buoyancy-engine-system" name="gz::sim::systems::BuoyancyEngine"><link_name>ballast_1</link_name><min_volume>0.0</min_volume><max_volume>0.003</max_volume><topic>/model/submarine/ballast_1/volume</topic></plugin>
    <plugin filename="gz-sim-buoyancy-engine-system" name="gz::sim::systems::BuoyancyEngine"><link_name>ballast_2</link_name><min_volume>0.0</min_volume><max_volume>0.003</max_volume><topic>/model/submarine/ballast_2/volume</topic></plugin>
    <plugin filename="gz-sim-buoyancy-engine-system" name="gz::sim::systems::BuoyancyEngine"><link_name>ballast_3</link_name><min_volume>0.0</min_volume><max_volume>0.003</max_volume><topic>/model/submarine/ballast_3/volume</topic></plugin>
    <plugin filename="gz-sim-buoyancy-engine-system" name="gz::sim::systems::BuoyancyEngine"><link_name>ballast_4</link_name><min_volume>0.0</min_volume><max_volume>0.003</max_volume><topic>/model/submarine/ballast_4/volume</topic></plugin>

    <!-- СИСТЕМНЫЕ ПЛАГИНЫ -->
    <plugin filename="gz-sim-odometry-publisher-system" name="gz::sim::systems::OdometryPublisher">
      <odom_frame>world</odom_frame><robot_base_frame>submarine/body</robot_base_frame>
      <odom_topic>/model/submarine/odometry</odom_topic><odom_publish_frequency>50</odom_publish_frequency>
    </plugin>

    <plugin filename="gz-sim-hydrodynamics-system" name="gz::sim::systems::Hydrodynamics">
      <link_name>body</link_name>
      <xU>-4.0</xU><xUabsU>-44.0</xUabsU><yV>-15.0</yV><yVabsV>-250.0</yVabsV><zW>-15.0</zW><zWabsW>-250.0</zWabsW>
      <kP>-1.0</kP><kPabsP>-10.0</kPabsP><mQ>-1.0</mQ><mQabsQ>-10.0</mQabsQ><nR>-1.0</nR><nRabsR>-10.0</nRabsR>
    </plugin>
    <plugin filename="gz-sim-hydrodynamics-system" name="gz::sim::systems::Hydrodynamics"><link_name>horizontal_rudder_right</link_name><xU>-0.2</xU><xUabsU>-0.5</xUabsU><yV>-0.4</yV><yVabsV>-1.0</yVabsV><zW>-0.4</zW><zWabsW>-1.0</zWabsW><kP>-0.02</kP><kPabsP>-0.05</kPabsP><mQ>-0.02</mQ><mQabsQ>-0.05</mQabsQ><nR>-0.02</nR><nRabsR>-0.05</nRabsR></plugin>
    <plugin filename="gz-sim-hydrodynamics-system" name="gz::sim::systems::Hydrodynamics"><link_name>horizontal_rudder_left</link_name><xU>-0.2</xU><xUabsU>-0.5</xUabsU><yV>-0.4</yV><yVabsV>-1.0</yVabsV><zW>-0.4</zW><zWabsW>-1.0</zWabsW><kP>-0.02</kP><kPabsP>-0.05</kPabsP><mQ>-0.02</mQ><mQabsQ>-0.05</mQabsQ><nR>-0.02</nR><nRabsR>-0.05</nRabsR></plugin>
    <plugin filename="gz-sim-hydrodynamics-system" name="gz::sim::systems::Hydrodynamics"><link_name>vertical_rudder</link_name><xU>-0.2</xU><xUabsU>-0.5</xUabsU><yV>-0.4</yV><yVabsV>-1.0</yVabsV><zW>-0.4</zW><zWabsW>-1.0</zWabsW><kP>-0.02</kP><kPabsP>-0.05</kPabsP><mQ>-0.02</mQ><mQabsQ>-0.05</mQabsQ><nR>-0.02</nR><nRabsR>-0.05</nRabsR></plugin>

  </model>
</sdf>
